notAnErrorSubtype-thrown-owned.chpl:5: In function 'main':
notAnErrorSubtype-thrown-owned.chpl:7: error: Cannot throw an instance of type 'Foo', not a subtype of Error
